<?xml version="1.0"?>
<robot name="robotic_arm">
<link name="base_link">
<visual>
<origin xyz="0.0024960130633573558712 0.12804634114627058694 -0.01108280622936548554" rpy="0 -0 0" />
<geometry>
<mesh filename="package://meshes/base_link.stl"/>
</geometry>
<material name="base_link_material">
<color rgba="0.61568627450980395466 0.81176470588235294379 0.92941176470588238168 1.0"/>
</material>
</visual>
<collision>
<origin xyz="0.0024960130633573558712 0.12804634114627058694 -0.01108280622936548554" rpy="0 -0 0" />
<geometry>
<mesh filename="package://meshes/base_link.stl"/>
</geometry>
</collision>
<inertial>
<origin xyz="0.0026174718339112084363 -0.0040148924014768716528 0.0049484920830945647308" rpy="0 0 0"/>
<mass value="0.1131732690462784463" />
<inertia ixx="9.856692962162541061e-05" ixy="6.0474343042231416637e-10"  ixz="1.5385565009010526225e-06" iyy="9.8537388460129794678e-05" iyz="2.9571407796833954483e-08" izz="0.0001786382600785708279" />
</inertial>
</link>

<link name="link_1">
<visual>
<origin xyz="0.058066221705191579938 -0.0010000035544516496996 0.035111317800536695488" rpy="-1.570796326794896558 -1.570796326794896558 0" />
<geometry>
<mesh filename="package://meshes/link_1.stl"/>
</geometry>
<material name="link_1_material">
<color rgba="0.49803921568627451677 0.49803921568627451677 0.49803921568627451677 1.0"/>
</material>
</visual>
<collision>
<origin xyz="0.058066221705191579938 -0.0010000035544516496996 0.035111317800536695488" rpy="-1.570796326794896558 -1.570796326794896558 0" />
<geometry>
<mesh filename="package://meshes/link_1.stl"/>
</geometry>
</collision>
<inertial>
<origin xyz="-0.0046815581201275560663 -3.350252841807224366e-06 0.024232949255673374989" rpy="0 0 0"/>
<mass value="0.080086465711985022065" />
<inertia ixx="0.00011439472559989889374" ixy="-1.0242629424710575339e-08"  ixz="5.1294106671647040892e-06" iyy="0.00010153371707618597843" iyz="3.0123150971127697935e-09" izz="9.4598706795031266151e-05" />
</inertial>
</link>

<link name="link_2">
<visual>
<origin xyz="0.058066756826188309359 0.00099999999999915933045 -0.043111317800536799738" rpy="1.570796326794896558 1.570796326794896558 0" />
<geometry>
<mesh filename="package://meshes/link_2.stl"/>
</geometry>
<material name="link_2_material">
<color rgba="0.98039215686274505668 0.71372549019607844922 0.0039215686274509803377 1.0"/>
</material>
</visual>
<collision>
<origin xyz="0.058066756826188309359 0.00099999999999915933045 -0.043111317800536799738" rpy="1.570796326794896558 1.570796326794896558 0" />
<geometry>
<mesh filename="package://meshes/link_2.stl"/>
</geometry>
</collision>
<inertial>
<origin xyz="0.1113556390516069472 1.2659493694219120519e-09 0.041180922428237384803" rpy="0 0 0"/>
<mass value="0.34014929780386427005" />
<inertia ixx="0.00032173805960381587606" ixy="-8.0176938346579620803e-11"  ixz="9.5203018742175472357e-07" iyy="0.0023827171157410368882" iyz="-1.8442351002073745675e-12" izz="0.0024099918968109521056" />
</inertial>
</link>

<link name="link_3">
<visual>
<origin xyz="-0.3889332431738120599 -0.0010000000000015309143 0.042111321354989406096" rpy="-1.570796326794896558 -1.570796326794896558 0" />
<geometry>
<mesh filename="package://meshes/link_3.stl"/>
</geometry>
<material name="link_3_material">
<color rgba="0.98039215686274505668 0.71372549019607844922 0.0039215686274509803377 1.0"/>
</material>
</visual>
<collision>
<origin xyz="-0.3889332431738120599 -0.0010000000000015309143 0.042111321354989406096" rpy="-1.570796326794896558 -1.570796326794896558 0" />
<geometry>
<mesh filename="package://meshes/link_3.stl"/>
</geometry>
</collision>
<inertial>
<origin xyz="-0.10832492980934992077 2.6923169470855625671e-05 0.039499194718111044211" rpy="0 0 0"/>
<mass value="0.31967748470292894902" />
<inertia ixx="0.00028140872177753425195" ixy="4.2487310578470514545e-07"  ixz="-0.00017337674379487602008" iyy="0.0024312861619251312402" iyz="-8.2724380357410980543e-09" izz="0.0023932480897531811792" />
</inertial>
</link>

<link name="link_4">
<visual>
<origin xyz="-0.38893324317381300359 0.0010000000000021103119 -0.043161592520954500385" rpy="1.570796326794896558 1.570796326794896558 0" />
<geometry>
<mesh filename="package://meshes/link_4.stl"/>
</geometry>
<material name="link_4_material">
<color rgba="0.98039215686274505668 0.71372549019607844922 0.0039215686274509803377 1.0"/>
</material>
</visual>
<collision>
<origin xyz="-0.38893324317381300359 0.0010000000000021103119 -0.043161592520954500385" rpy="1.570796326794896558 1.570796326794896558 0" />
<geometry>
<mesh filename="package://meshes/link_4.stl"/>
</geometry>
</collision>
<inertial>
<origin xyz="-0.0063134084365573106545 -4.1715671044378378751e-05 0.032316899623642203476" rpy="0 0 0"/>
<mass value="0.095178714940116454502" />
<inertia ixx="9.9208805832435477813e-05" ixy="-7.2909475073240143536e-08"  ixz="8.6738950255301555198e-06" iyy="0.00012486179767824879443" iyz="-1.5771532401003181864e-08" izz="0.00010870685746829237335" />
</inertial>
</link>

<link name="link_5">
<visual>
<origin xyz="0.085161592520954398911 0.0010125586032828232108 -0.42993324317381198529" rpy="1.570796326794896558 1.3040595762004301237e-18 6.4830711884908311151e-22" />
<geometry>
<mesh filename="package://meshes/link_5.stl"/>
</geometry>
<material name="link_5_material">
<color rgba="0.98039215686274505668 0.71372549019607844922 0.0039215686274509803377 1.0"/>
</material>
</visual>
<collision>
<origin xyz="0.085161592520954398911 0.0010125586032828232108 -0.42993324317381198529" rpy="1.570796326794896558 1.3040595762004301237e-18 6.4830711884908311151e-22" />
<geometry>
<mesh filename="package://meshes/link_5.stl"/>
</geometry>
</collision>
<inertial>
<origin xyz="0.0063173930940050998517 -1.5991599702916154541e-05 0.032316925865712553545" rpy="0 0 0"/>
<mass value="0.095178710281144468519" />
<inertia ixx="9.9208799430564826379e-05" ixy="5.9725984991816655986e-08"  ixz="-8.6777151419389535132e-06" iyy="0.00012482622378922315584" iyz="-3.8040866501322656934e-08" izz="0.00010867121720011838168" />
</inertial>
</link>

<joint name="joint_5" type="revolute">
<origin xyz="0.040999999999999203748 -1.2558603280719404099e-05 0.041999999999999801381" rpy="-1.57079632679489678 -1.3881895319257544894e-16 -1.570796326794896558" />
<parent link="link_4" />
<child link="link_5" />
<axis xyz="0 0 1"/>
<limit effort="1" velocity="20" lower="-1.57" upper="1.57/>
<joint_properties friction="0.0"/>
</joint>

<joint name="joint_4" type="revolute">
<origin xyz="-0.22099999999999997424 -4.7748263676261615274e-16 -2.0122792321330962295e-16" rpy="-3.1415926535897797933 1.6514832745936422549e-14 3.1415926535897904515" />
<parent link="link_3" />
<child link="link_4" />
<axis xyz="0 0 1"/>
<limit effort="1" velocity="20" lower="-1.57" upper="1.57/>
<joint_properties friction="0.0"/>
</joint>

<joint name="joint_3" type="revolute">
<origin xyz="0.22600000000000031175 -1.6093897048374827818e-15 3.5544528015352128136e-09" rpy="-3.1415926535897842342 4.2771596214354794764e-15 3.1415926535897913396" />
<parent link="link_2" />
<child link="link_3" />
<axis xyz="0 0 1"/>
<limit effort="1" velocity="20" lower="-1.57" upper="1.57/>
<joint_properties friction="0.0"/>
</joint>

<joint name="joint_2" type="revolute">
<origin xyz="-0.043800535120997539928 -0.00017721450937848055862 0.035099745291068740194" rpy="1.8403916892873062454e-17 -1.570796326794896558 0" />
<parent link="link_1" />
<child link="link_2" />
<axis xyz="0 0 1"/>
<limit effort="1" velocity="20" lower="-1.57" upper="1.57/>
<joint_properties friction="0.0"/>
</joint>

<joint name="joint_1" type="revolute">
<origin xyz="0.0029030429781492428018 -0.0040093955121447213963 0.016911150880017183917" rpy="0.019200131903186444526 0.0003688037187457633855 1.570796326794896558" />
<parent link="base_link" />
<child link="link_1" />
<axis xyz="0 0 1"/>
<limit effort="1" velocity="20" lower="-1.57" upper="1.57/>
<joint_properties friction="0.0"/>
</joint>


</robot>
